Workbook

Sheet Bike_Sales_Functions_Lab
A1: Sales_Order # | B1: Date | C1: Day | D1: Month | E1: Year | F1: Customer_Age | G1: Age_Group | H1: Customer_Gender | I1: Country | J1: State | K1: Product_Category | L1: Sub_Category | M1: Product_Description | N1: Order_Quantity | O1: Unit_Cost | P1: Unit_Price | Q1: Profit | R1: Cost | S1: Revenue
A2: 000261695 | B2: 44531 | C2: 1 | D2: December | E2: 2021 | F2: 39 | G2: Adults (35-64) | H2: F | I2: United States | J2: California | K2: Bikes | L2: Mountain Bikes | M2: Mountain-200 Black, 46 | N2: 4 | O2: 1252 | P2: 2295 | Q2: 4172 | R2: 5008 | S2: 9180
A3: 000261696 | B3: 44531 | C3: 1 | D3: December | E3: 2021 | F3: 44 | G3: Adults (35-64) | H3: M | I3: United Kingdom | J3: England | K3: Bikes | L3: Mountain Bikes | M3: Mountain-200 Silver, 42 | N3: 1 | O3: 1266 | P3: 2320 | Q3: 1054 | R3: 1266 | S3: 2320
A4: 000261697 | B4: 44532 | C4: 2 | D4: December | E4: 2021 | F4: 37 | G4: Adults (35-64) | H4: M | I4: United States | J4: California | K4: Bikes | L4: Mountain Bikes | M4: Mountain-400-W Silver, 46 | N4: 2 | O4: 420 | P4: 769 | Q4: 698 | R4: 840 | S4: 1538
A5: 000261698 | B5: 44532 | C5: 2 | D5: December | E5: 2021 | F5: 31 | G5: Young Adults (25-34) | H5: F | I5: Australia | J5: New South Wales | K5: Bikes | L5: Mountain Bikes | M5: Mountain-400-W Silver, 42 | N5: 1 | O5: 420 | P5: 769 | Q5: 349 | R5: 420 | S5: 769
A6: 000261699 | B6: 44533 | C6: 3 | D6: December | E6: 2021 | F6: 37 | G6: Adults (35-64) | H6: F | I6: United States | J6: California | K6: Bikes | L6: Mountain Bikes | M6: Mountain-200 Black, 46 | N6: 2 | O6: 1252 | P6: 2295 | Q6: 2086 | R6: 2504 | S6: 4590
A7: 000261700 | B7: 44533 | C7: 3 | D7: December | E7: 2021 | F7: 24 | G7: Youth (<25) | H7: F | I7: United Kingdom | J7: England | K7: Bikes | L7: Mountain Bikes | M7: Mountain-200 Black, 38 | N7: 1 | O7: 1252 | P7: 2295 | Q7: 1043 | R7: 1252 | S7: 2295
A8: 000261701 | B8: 44533 | C8: 3 | D8: December | E8: 2021 | F8: 37 | G8: Adults (35-64) | H8: M | I8: United States | J8: Washington | K8: Bikes | L8: Mountain Bikes | M8: Mountain-200 Black, 46 | N8: 1 | O8: 1252 | P8: 2295 | Q8: 1043 | R8: 1252 | S8: 2295
A9: 000261702 | B9: 44534 | C9: 4 | D9: December | E9: 2021 | F9: 31 | G9: Young Adults (25-34) | H9: F | I9: Australia | J9: New South Wales | K9: Bikes | L9: Mountain Bikes | M9: Mountain-400-W Silver, 42 | N9: 4 | O9: 420 | P9: 769 | Q9: 1396 | R9: 1680 | S9: 3076
A10: 000261703 | B10: 44535 | C10: 5 | D10: December | E10: 2021 | F10: 39 | G10: Adults (35-64) | H10: F | I10: United States | J10: California | K10: Bikes | L10: Mountain Bikes | M10: Mountain-200 Black, 46 | N10: 4 | O10: 1252 | P10: 2295 | Q10: 4172 | R10: 5008 | S10: 9180
A11: 000261704 | B11: 44535 | C11: 5 | D11: December | E11: 2021 | F11: 42 | G11: Adults (35-64) | H11: M | I11: Germany | J11: Nordrhein-Westfalen | K11: Bikes | L11: Mountain Bikes | M11: Mountain-200 Black, 38 | N11: 4 | O11: 1252 | P11: 2295 | Q11: 4172 | R11: 5008 | S11: 9180
A12: 000261705 | B12: 44535 | C12: 5 | D12: December | E12: 2021 | F12: 35 | G12: Adults (35-64) | H12: F | I12: Australia | J12: Queensland | K12: Bikes | L12: Mountain Bikes | M12: Mountain-200 Silver, 38 | N12: 1 | O12: 1266 | P12: 2320 | Q12: 1054 | R12: 1266 | S12: 2320
A13: 000261706 | B13: 44535 | C13: 5 | D13: December | E13: 2021 | F13: 37 | G13: Adults (35-64) | H13: F | I13: United States | J13: California | K13: Bikes | L13: Mountain Bikes | M13: Mountain-200 Black, 46 | N13: 1 | O13: 1252 | P13: 2295 | Q13: 1043 | R13: 1252 | S13: 2295
... A89: 000261782 | B89: 44554 | C89: 24 | D89: December | E89: 2021 | F89: 38 | G89: Adults (35-64) | H89: M | I89: Australia | J89: Queensland | K89: Bikes | L89: Mountain Bikes | M89: Mountain-200 Black, 42 | N89: 4 | O89: 1252 | P89: 2295 | Q89: 4172 | R89: 5008 | S89: 9180

Sheet Functions and Formulas done
A1: Age Group | B1: Average Revenue per group | D1: Concatenated values | F1: Separated data: Model | G1: Separated data: Color | H1: Separated data: Size | J1: Minimum Revenue from Australia | K1: Maximum Revenue from Australia
A2: Youth | B2: =AVERAGEIF(Bike_Sales_Functions_Lab!G2:G89,"Youth (<25)",Bike_Sales_Functions_Lab!S2:S89) -> 3533 | D2: =CONCATENATE(Bike_Sales_Functions_Lab!A2,": ", Bike_Sales_Functions_Lab!N2," ",Bike_Sales_Functions_Lab!L2," - ",TEXT(Bike_Sales_Functions_Lab!B2,"mm/dd/yyyy")) -> 000261695: 4 Mountain Bikes - 12/01/2021 | F2: =LEFT(Bike_Sales_Functions_Lab!M2,12) -> Mountain-200 | G2: =MID(Bike_Sales_Functions_Lab!M2,13,6) -> Black | H2: =RIGHT(Bike_Sales_Functions_Lab!M2, 2) -> 46 | J2: =_xlfn.MINIFS(Bike_Sales_Functions_Lab!S2:S89, Bike_Sales_Functions_Lab!I2:I89, "Australia") -> 565 | K2: =_xlfn.MAXIFS(Bike_Sales_Functions_Lab!S2:S89, Bike_Sales_Functions_Lab!I2:I89, "Australia") -> 13500
A3: Young Adults | B3: =AVERAGEIF(Bike_Sales_Functions_Lab!G2:G89,"Young Adults (25-34)",Bike_Sales_Functions_Lab!S2:S89) -> 3859.5484 | D3: =CONCATENATE(Bike_Sales_Functions_Lab!A3,": ", Bike_Sales_Functions_Lab!N3," ",Bike_Sales_Functions_Lab!L3," - ",TEXT(Bike_Sales_Functions_Lab!B3,"mm/dd/yyyy")) -> 000261696: 1 Mountain Bikes - 12/01/2021 | F3: =LEFT(Bike_Sales_Functions_Lab!M3,12) -> Mountain-200 | G3: =MID(Bike_Sales_Functions_Lab!M3,13,7) -> Silver | H3: =RIGHT(Bike_Sales_Functions_Lab!M3, 2) -> 42
A4: Adults | B4: =AVERAGEIF(Bike_Sales_Functions_Lab!G2:G89,"Adults (35-64)",Bike_Sales_Functions_Lab!S2:S89) -> 4388.4255 | D4: =CONCATENATE(Bike_Sales_Functions_Lab!A4,": ", Bike_Sales_Functions_Lab!N4," ",Bike_Sales_Functions_Lab!L4," - ",TEXT(Bike_Sales_Functions_Lab!B4,"mm/dd/yyyy")) -> 000261697: 2 Mountain Bikes - 12/02/2021 | F4: =LEFT(Bike_Sales_Functions_Lab!M4,14) -> Mountain-400-W | G4: =MID(Bike_Sales_Functions_Lab!M4,16,6) -> Silver | H4: =RIGHT(Bike_Sales_Functions_Lab!M4, 2) -> 46
D5: =CONCATENATE(Bike_Sales_Functions_Lab!A5,": ", Bike_Sales_Functions_Lab!N5," ",Bike_Sales_Functions_Lab!L5," - ",TEXT(Bike_Sales_Functions_Lab!B5,"mm/dd/yyyy")) -> 000261698: 1 Mountain Bikes - 12/02/2021 | F5: =LEFT(Bike_Sales_Functions_Lab!M5,14) -> Mountain-400-W | G5: =MID(Bike_Sales_Functions_Lab!M5,16,6) -> Silver | H5: =RIGHT(Bike_Sales_Functions_Lab!M5, 2) -> 42
D6: =CONCATENATE(Bike_Sales_Functions_Lab!A6,": ", Bike_Sales_Functions_Lab!N6," ",Bike_Sales_Functions_Lab!L6," - ",TEXT(Bike_Sales_Functions_Lab!B6,"mm/dd/yyyy")) -> 000261699: 2 Mountain Bikes - 12/03/2021 | F6: =LEFT(Bike_Sales_Functions_Lab!M6,12) -> Mountain-200 | G6: =MID(Bike_Sales_Functions_Lab!M6,13,6) -> Black | H6: =RIGHT(Bike_Sales_Functions_Lab!M6, 2) -> 46 | J6: Sum of Revenue from Australia
D7: =CONCATENATE(Bike_Sales_Functions_Lab!A7,": ", Bike_Sales_Functions_Lab!N7," ",Bike_Sales_Functions_Lab!L7," - ",TEXT(Bike_Sales_Functions_Lab!B7,"mm/dd/yyyy")) -> 000261700: 1 Mountain Bikes - 12/03/2021 | F7: =LEFT(Bike_Sales_Functions_Lab!M7,12) -> Mountain-200 | G7: =MID(Bike_Sales_Functions_Lab!M7,13,6) -> Black | H7: =RIGHT(Bike_Sales_Functions_Lab!M7, 2) -> 38 | J7: =SUMIF(Bike_Sales_Functions_Lab!I2:I89, "Australia", Bike_Sales_Functions_Lab!S2:S89) -> 111506
D8: =CONCATENATE(Bike_Sales_Functions_Lab!A8,": ", Bike_Sales_Functions_Lab!N8," ",Bike_Sales_Functions_Lab!L8," - ",TEXT(Bike_Sales_Functions_Lab!B8,"mm/dd/yyyy")) -> 000261701: 1 Mountain Bikes - 12/03/2021 | F8: =LEFT(Bike_Sales_Functions_Lab!M8,12) -> Mountain-200 | G8: =MID(Bike_Sales_Functions_Lab!M8,13,6) -> Black | H8: =RIGHT(Bike_Sales_Functions_Lab!M8, 2) -> 46
D9: =CONCATENATE(Bike_Sales_Functions_Lab!A9,": ", Bike_Sales_Functions_Lab!N9," ",Bike_Sales_Functions_Lab!L9," - ",TEXT(Bike_Sales_Functions_Lab!B9,"mm/dd/yyyy")) -> 000261702: 4 Mountain Bikes - 12/04/2021 | F9: =LEFT(Bike_Sales_Functions_Lab!M9,14) -> Mountain-400-W | G9: =MID(Bike_Sales_Functions_Lab!M9,16,6) -> Silver | H9: =RIGHT(Bike_Sales_Functions_Lab!M9, 2) -> 42
D10: =CONCATENATE(Bike_Sales_Functions_Lab!A10,": ", Bike_Sales_Functions_Lab!N10," ",Bike_Sales_Functions_Lab!L10," - ",TEXT(Bike_Sales_Functions_Lab!B10,"mm/dd/yyyy")) -> 000261703: 4 Mountain Bikes - 12/05/2021 | F10: =LEFT(Bike_Sales_Functions_Lab!M10,12) -> Mountain-200 | G10: =MID(Bike_Sales_Functions_Lab!M10,13,6) -> Black | H10: =RIGHT(Bike_Sales_Functions_Lab!M10, 2) -> 46
D11: =CONCATENATE(Bike_Sales_Functions_Lab!A11,": ", Bike_Sales_Functions_Lab!N11," ",Bike_Sales_Functions_Lab!L11," - ",TEXT(Bike_Sales_Functions_Lab!B11,"mm/dd/yyyy")) -> 000261704: 4 Mountain Bikes - 12/05/2021 | F11: =LEFT(Bike_Sales_Functions_Lab!M11,12) -> Mountain-200 | G11: =MID(Bike_Sales_Functions_Lab!M11,13,6) -> Black | H11: =RIGHT(Bike_Sales_Functions_Lab!M11, 2) -> 38
D12: =CONCATENATE(Bike_Sales_Functions_Lab!A12,": ", Bike_Sales_Functions_Lab!N12," ",Bike_Sales_Functions_Lab!L12," - ",TEXT(Bike_Sales_Functions_Lab!B12,"mm/dd/yyyy")) -> 000261705: 1 Mountain Bikes - 12/05/2021 | F12: =LEFT(Bike_Sales_Functions_Lab!M12,12) -> Mountain-200 | G12: =MID(Bike_Sales_Functions_Lab!M12,13,7) -> Silver | H12: =RIGHT(Bike_Sales_Functions_Lab!M12, 2) -> 38
D13: =CONCATENATE(Bike_Sales_Functions_Lab!A13,": ", Bike_Sales_Functions_Lab!N13," ",Bike_Sales_Functions_Lab!L13," - ",TEXT(Bike_Sales_Functions_Lab!B13,"mm/dd/yyyy")) -> 000261706: 1 Mountain Bikes - 12/05/2021 | F13: =LEFT(Bike_Sales_Functions_Lab!M13,12) -> Mountain-200 | G13: =MID(Bike_Sales_Functions_Lab!M13,13,6) -> Black | H13: =RIGHT(Bike_Sales_Functions_Lab!M13, 2) -> 46
D14: =CONCATENATE(Bike_Sales_Functions_Lab!A14,": ", Bike_Sales_Functions_Lab!N14," ",Bike_Sales_Functions_Lab!L14," - ",TEXT(Bike_Sales_Functions_Lab!B14,"mm/dd/yyyy")) -> 000261707: 3 Mountain Bikes - 12/06/2021 | F14: =LEFT(Bike_Sales_Functions_Lab!M14,14) -> Mountain-400-W | G14: =MID(Bike_Sales_Functions_Lab!M14,16,6) -> Silver | H14: =RIGHT(Bike_Sales_Functions_Lab!M14, 2) -> 46
D15: =CONCATENATE(Bike_Sales_Functions_Lab!A15,": ", Bike_Sales_Functions_Lab!N15," ",Bike_Sales_Functions_Lab!L15," - ",TEXT(Bike_Sales_Functions_Lab!B15,"mm/dd/yyyy")) -> 000261708: 1 Mountain Bikes - 12/06/2021 | F15: =LEFT(Bike_Sales_Functions_Lab!M15,12) -> Mountain-200 | G15: =MID(Bike_Sales_Functions_Lab!M15,13,6) -> Black | H15: =RIGHT(Bike_Sales_Functions_Lab!M15, 2) -> 46
D16: =CONCATENATE(Bike_Sales_Functions_Lab!A16,": ", Bike_Sales_Functions_Lab!N16," ",Bike_Sales_Functions_Lab!L16," - ",TEXT(Bike_Sales_Functions_Lab!B16,"mm/dd/yyyy")) -> 000261709: 1 Mountain Bikes - 12/06/2021 | F16: =LEFT(Bike_Sales_Functions_Lab!M16,12) -> Mountain-200 | G16: =MID(Bike_Sales_Functions_Lab!M16,13,6) -> Black | H16: =RIGHT(Bike_Sales_Functions_Lab!M16, 2) -> 42
D17: =CONCATENATE(Bike_Sales_Functions_Lab!A17,": ", Bike_Sales_Functions_Lab!N17," ",Bike_Sales_Functions_Lab!L17," - ",TEXT(Bike_Sales_Functions_Lab!B17,"mm/dd/yyyy")) -> 000261710: 1 Mountain Bikes - 12/06/2021 | F17: =LEFT(Bike_Sales_Functions_Lab!M17,12) -> Mountain-200 | G17: =MID(Bike_Sales_Functions_Lab!M17,13,7) -> Silver | H17: =RIGHT(Bike_Sales_Functions_Lab!M17, 2) -> 38
D18: =CONCATENATE(Bike_Sales_Functions_Lab!A18,": ", Bike_Sales_Functions_Lab!N18," ",Bike_Sales_Functions_Lab!L18," - ",TEXT(Bike_Sales_Functions_Lab!B18,"mm/dd/yyyy")) -> 000261711: 4 Mountain Bikes - 12/07/2021 | F18: =LEFT(Bike_Sales_Functions_Lab!M18,14) -> Mountain-400-W | G18: =MID(Bike_Sales_Functions_Lab!M18,16,6) -> Silver | H18: =RIGHT(Bike_Sales_Functions_Lab!M18, 2) -> 38
D19: =CONCATENATE(Bike_Sales_Functions_Lab!A19,": ", Bike_Sales_Functions_Lab!N19," ",Bike_Sales_Functions_Lab!L19," - ",TEXT(Bike_Sales_Functions_Lab!B19,"mm/dd/yyyy")) -> 000261712: 2 Mountain Bikes - 12/07/2021 | F19: =LEFT(Bike_Sales_Functions_Lab!M19,12) -> Mountain-200 | G19: =MID(Bike_Sales_Functions_Lab!M19,13,7) -> Silver | H19: =RIGHT(Bike_Sales_Functions_Lab!M19, 2) -> 42
D20: =CONCATENATE(Bike_Sales_Functions_Lab!A20,": ", Bike_Sales_Functions_Lab!N20," ",Bike_Sales_Functions_Lab!L20," - ",TEXT(Bike_Sales_Functions_Lab!B20,"mm/dd/yyyy")) -> 000261713: 4 Mountain Bikes - 12/08/2021 | F20: =LEFT(Bike_Sales_Functions_Lab!M20,12) -> Mountain-500 | G20: =MID(Bike_Sales_Functions_Lab!M20,13,7) -> Silver | H20: =RIGHT(Bike_Sales_Functions_Lab!M20, 2) -> 42
D21: =CONCATENATE(Bike_Sales_Functions_Lab!A21,": ", Bike_Sales_Functions_Lab!N21," ",Bike_Sales_Functions_Lab!L21," - ",TEXT(Bike_Sales_Functions_Lab!B21,"mm/dd/yyyy")) -> 000261714: 4 Mountain Bikes - 12/08/2021 | F21: =LEFT(Bike_Sales_Functions_Lab!M21,12) -> Mountain-200 | G21: =MID(Bike_Sales_Functions_Lab!M21,13,7) -> Silver | H21: =RIGHT(Bike_Sales_Functions_Lab!M21, 2) -> 38
D22: =CONCATENATE(Bike_Sales_Functions_Lab!A22,": ", Bike_Sales_Functions_Lab!N22," ",Bike_Sales_Functions_Lab!L22," - ",TEXT(Bike_Sales_Functions_Lab!B22,"mm/dd/yyyy")) -> 000261715: 2 Mountain Bikes - 12/08/2021 | F22: =LEFT(Bike_Sales_Functions_Lab!M22,12) -> Mountain-200 | G22: =MID(Bike_Sales_Functions_Lab!M22,13,6) -> Black | H22: =RIGHT(Bike_Sales_Functions_Lab!M22, 2) -> 42
D23: =CONCATENATE(Bike_Sales_Functions_Lab!A23,": ", Bike_Sales_Functions_Lab!N23," ",Bike_Sales_Functions_Lab!L23," - ",TEXT(Bike_Sales_Functions_Lab!B23,"mm/dd/yyyy")) -> 000261716: 1 Mountain Bikes - 12/08/2021 | F23: =LEFT(Bike_Sales_Functions_Lab!M23,12) -> Mountain-500 | G23: =MID(Bike_Sales_Functions_Lab!M23,13,6) -> Black | H23: =RIGHT(Bike_Sales_Functions_Lab!M23, 2) -> 42
D24: =CONCATENATE(Bike_Sales_Functions_Lab!A24,": ", Bike_Sales_Functions_Lab!N24," ",Bike_Sales_Functions_Lab!L24," - ",TEXT(Bike_Sales_Functions_Lab!B24,"mm/dd/yyyy")) -> 000261717: 2 Mountain Bikes - 12/09/2021 | F24: =LEFT(Bike_Sales_Functions_Lab!M24,12) -> Mountain-100 | G24: =MID(Bike_Sales_Functions_Lab!M24,13,6) -> Black | H24: =RIGHT(Bike_Sales_Functions_Lab!M24, 2) -> 38
D25: =CONCATENATE(Bike_Sales_Functions_Lab!A25,": ", Bike_Sales_Functions_Lab!N25," ",Bike_Sales_Functions_Lab!L25," - ",TEXT(Bike_Sales_Functions_Lab!B25,"mm/dd/yyyy")) -> 000261718: 1 Mountain Bikes - 12/09/2021 | F25: =LEFT(Bike_Sales_Functions_Lab!M25,12) -> Mountain-200 | G25: =MID(Bike_Sales_Functions_Lab!M25,13,7) -> Silver | H25: =RIGHT(Bike_Sales_Functions_Lab!M25, 2) -> 42
D26: =CONCATENATE(Bike_Sales_Functions_Lab!A26,": ", Bike_Sales_Functions_Lab!N26," ",Bike_Sales_Functions_Lab!L26," - ",TEXT(Bike_Sales_Functions_Lab!B26,"mm/dd/yyyy")) -> 000261719: 2 Mountain Bikes - 12/10/2021 | F26: =LEFT(Bike_Sales_Functions_Lab!M26,12) -> Mountain-200 | G26: =MID(Bike_Sales_Functions_Lab!M26,13,6) -> Black | H26: =RIGHT(Bike_Sales_Functions_Lab!M26, 2) -> 42
D27: =CONCATENATE(Bike_Sales_Functions_Lab!A27,": ", Bike_Sales_Functions_Lab!N27," ",Bike_Sales_Functions_Lab!L27," - ",TEXT(Bike_Sales_Functions_Lab!B27,"mm/dd/yyyy")) -> 000261720: 2 Mountain Bikes - 12/10/2021 | F27: =LEFT(Bike_Sales_Functions_Lab!M27,12) -> Mountain-200 | G27: =MID(Bike_Sales_Functions_Lab!M27,13,6) -> Black | H27: =RIGHT(Bike_Sales_Functions_Lab!M27, 2) -> 42
D28: =CONCATENATE(Bike_Sales_Functions_Lab!A28,": ", Bike_Sales_Functions_Lab!N28," ",Bike_Sales_Functions_Lab!L28," - ",TEXT(Bike_Sales_Functions_Lab!B28,"mm/dd/yyyy")) -> 000261721: 1 Mountain Bikes - 12/10/2021 | F28: =LEFT(Bike_Sales_Functions_Lab!M28,12) -> Mountain-200 | G28: =MID(Bike_Sales_Functions_Lab!M28,13,6) -> Black | H28: =RIGHT(Bike_Sales_Functions_Lab!M28, 2) -> 38
D29: =CONCATENATE(Bike_Sales_Functions_Lab!A29,": ", Bike_Sales_Functions_Lab!N29," ",Bike_Sales_Functions_Lab!L29," - ",TEXT(Bike_Sales_Functions_Lab!B29,"mm/dd/yyyy")) -> 000261722: 1 Mountain Bikes - 12/10/2021 | F29: =LEFT(Bike_Sales_Functions_Lab!M29,12) -> Mountain-500 | G29: =MID(Bike_Sales_Functions_Lab!M29,13,6) -> Black | H29: =RIGHT(Bike_Sales_Functions_Lab!M29, 2) -> 40
D30: =CONCATENATE(Bike_Sales_Functions_Lab!A30,": ", Bike_Sales_Functions_Lab!N30," ",Bike_Sales_Functions_Lab!L30," - ",TEXT(Bike_Sales_Functions_Lab!B30,"mm/dd/yyyy")) -> 000261723: 1 Mountain Bikes - 12/10/2021 | F30: =LEFT(Bike_Sales_Functions_Lab!M30,12) -> Mountain-100 | G30: =MID(Bike_Sales_Functions_Lab!M30,13,7) -> Silver | H30: =RIGHT(Bike_Sales_Functions_Lab!M30, 2) -> 44
D31: =CONCATENATE(Bike_Sales_Functions_Lab!A31,": ", Bike_Sales_Functions_Lab!N31," ",Bike_Sales_Functions_Lab!L31," - ",TEXT(Bike_Sales_Functions_Lab!B31,"mm/dd/yyyy")) -> 000261724: 1 Mountain Bikes - 12/10/2021 | F31: =LEFT(Bike_Sales_Functions_Lab!M31,12) -> Mountain-200 | G31: =MID(Bike_Sales_Functions_Lab!M31,13,6) -> Black | H31: =RIGHT(Bike_Sales_Functions_Lab!M31, 2) -> 38
D32: =CONCATENATE(Bike_Sales_Functions_Lab!A32,": ", Bike_Sales_Functions_Lab!N32," ",Bike_Sales_Functions_Lab!L32," - ",TEXT(Bike_Sales_Functions_Lab!B32,"mm/dd/yyyy")) -> 000261725: 3 Mountain Bikes - 12/11/2021 | F32: =LEFT(Bike_Sales_Functions_Lab!M32,12) -> Mountain-200 | G32: =MID(Bike_Sales_Functions_Lab!M32,13,6) -> Black | H32: =RIGHT(Bike_Sales_Functions_Lab!M32, 2) -> 38
D33: =CONCATENATE(Bike_Sales_Functions_Lab!A33,": ", Bike_Sales_Functions_Lab!N33," ",Bike_Sales_Functions_Lab!L33," - ",TEXT(Bike_Sales_Functions_Lab!B33,"mm/dd/yyyy")) -> 000261726: 2 Mountain Bikes - 12/11/2021 | F33: =LEFT(Bike_Sales_Functions_Lab!M33,14) -> Mountain-400-W | G33: =MID(Bike_Sales_Functions_Lab!M33,16,6) -> Silver | H33: =RIGHT(Bike_Sales_Functions_Lab!M33, 2) -> 38
D34: =CONCATENATE(Bike_Sales_Functions_Lab!A34,": ", Bike_Sales_Functions_Lab!N34," ",Bike_Sales_Functions_Lab!L34," - ",TEXT(Bike_Sales_Functions_Lab!B34,"mm/dd/yyyy")) -> 000261727: 1 Mountain Bikes - 12/11/2021 | F34: =LEFT(Bike_Sales_Functions_Lab!M34,12) -> Mountain-200 | G34: =MID(Bike_Sales_Functions_Lab!M34,13,6) -> Black | H34: =RIGHT(Bike_Sales_Functions_Lab!M34, 2) -> 46
D35: =CONCATENATE(Bike_Sales_Functions_Lab!A35,": ", Bike_Sales_Functions_Lab!N35," ",Bike_Sales_Functions_Lab!L35," - ",TEXT(Bike_Sales_Functions_Lab!B35,"mm/dd/yyyy")) -> 000261728: 1 Mountain Bikes - 12/11/2021 | F35: =LEFT(Bike_Sales_Functions_Lab!M35,14) -> Mountain-400-W | G35: =MID(Bike_Sales_Functions_Lab!M35,16,6) -> Silver | H35: =RIGHT(Bike_Sales_Functions_Lab!M35, 2) -> 46
D36: =CONCATENATE(Bike_Sales_Functions_Lab!A36,": ", Bike_Sales_Functions_Lab!N36," ",Bike_Sales_Functions_Lab!L36," - ",TEXT(Bike_Sales_Functions_Lab!B36,"mm/dd/yyyy")) -> 000261729: 1 Mountain Bikes - 12/11/2021 | F36: =LEFT(Bike_Sales_Functions_Lab!M36,12) -> Mountain-200 | G36: =MID(Bike_Sales_Functions_Lab!M36,13,7) -> Silver | H36: =RIGHT(Bike_Sales_Functions_Lab!M36, 2) -> 38
D37: =CONCATENATE(Bike_Sales_Functions_Lab!A37,": ", Bike_Sales_Functions_Lab!N37," ",Bike_Sales_Functions_Lab!L37," - ",TEXT(Bike_Sales_Functions_Lab!B37,"mm/dd/yyyy")) -> 000261730: 4 Mountain Bikes - 12/12/2021 | F37: =LEFT(Bike_Sales_Functions_Lab!M37,12) -> Mountain-200 | G37: =MID(Bike_Sales_Functions_Lab!M37,13,7) -> Silver | H37: =RIGHT(Bike_Sales_Functions_Lab!M37, 2) -> 42
D38: =CONCATENATE(Bike_Sales_Functions_Lab!A38,": ", Bike_Sales_Functions_Lab!N38," ",Bike_Sales_Functions_Lab!L38," - ",TEXT(Bike_Sales_Functions_Lab!B38,"mm/dd/yyyy")) -> 000261731: 4 Mountain Bikes - 12/12/2021 | F38: =LEFT(Bike_Sales_Functions_Lab!M38,14) -> Mountain-400-W | G38: =MID(Bike_Sales_Functions_Lab!M38,16,6) -> Silver | H38: =RIGHT(Bike_Sales_Functions_Lab!M38, 2) -> 46
D39: =CONCATENATE(Bike_Sales_Functions_Lab!A39,": ", Bike_Sales_Functions_Lab!N39," ",Bike_Sales_Functions_Lab!L39," - ",TEXT(Bike_Sales_Functions_Lab!B39,"mm/dd/yyyy")) -> 000261732: 2 Mountain Bikes - 12/12/2021 | F39: =LEFT(Bike_Sales_Functions_Lab!M39,12) -> Mountain-200 | G39: =MID(Bike_Sales_Functions_Lab!M39,13,6) -> Black | H39: =RIGHT(Bike_Sales_Functions_Lab!M39, 2) -> 38
D40: =CONCATENATE(Bike_Sales_Functions_Lab!A40,": ", Bike_Sales_Functions_Lab!N40," ",Bike_Sales_Functions_Lab!L40," - ",TEXT(Bike_Sales_Functions_Lab!B40,"mm/dd/yyyy")) -> 000261733: 1 Mountain Bikes - 12/12/2021 | F40: =LEFT(Bike_Sales_Functions_Lab!M40,12) -> Mountain-200 | G40: =MID(Bike_Sales_Functions_Lab!M40,13,7) -> Silver | H40: =RIGHT(Bike_Sales_Functions_Lab!M40, 2) -> 42
...
